

```python
import re
import tkinter
QQstr = """

"""
```


```python
def go():
    print(text.get("0.0","end"))
    print(type(text.get("0.0","end")))
    mylist  = re.findall("[1-9]\\d{4,10}",text.get("0.0","end"))
    print(mylist)
    for QQ in mylist:
        QQ += "@qq.com"
        list.insert(tkinter.END,QQ)
    pass
```


```python
win = tkinter.Tk()
button = tkinter.Button(win, text = "提取",command = go )
button.pack()

text = tkinter.Text(win)
text.insert(tkinter.INSERT,QQstr)
text.pack()
win.mainloop()
```

    
    
    vid	曹传宇	8276	13925288521	0755-25831029	10054	1054	david@tencent.com
    agong	贡海星	8267	13823240555	83850696	10018/28038	1018	agong@tencent.com
    hunter	刘化静	8277	13823202677	82268556	10040	1040	hunter@tencent.com
    norman	于　锐	8253	13501550210		10037	1037	yr@tencent.com
    king	王  星	8119	13828786611		10158	1158	king@tencent.com
    emma	刘旭民				80000781	8781	emma@tencent.com
    ring	张彦玲	8409	13928478661		80000768	8768	ring@tencent.com
    
    <class 'str'>
    ['13925288521', '25831029', '10054', '13823240555', '83850696', '10018', '28038', '13823202677', '82268556', '10040', '13501550210', '10037', '13828786611', '10158', '80000781', '13928478661', '80000768']
    

    Exception in Tkinter callback
    Traceback (most recent call last):
      File "C:\Users\money\Anaconda3\lib\tkinter\__init__.py", line 1702, in __call__
        return self.func(*args)
      File "<ipython-input-29-5aff54ee2484>", line 8, in go
        list.insert(tkinter.END,QQ)
    TypeError: descriptor 'insert' requires a 'list' object but received a 'str'
    

    
    
    vid	曹传宇	8276	13925288521	0755-25831029	10054	1054	david@tencent.com
    agong	贡海星	8267	13823240555	83850696	10018/28038	1018	agong@tencent.com
    hunter	刘化静	8277	13823202677	82268556	10040	1040	hunter@tencent.com
    norman	于　锐	8253	13501550210		10037	1037	yr@tencent.com
    king	王  星	8119	13828786611		10158	1158	king@tencent.com
    emma	刘旭民				80000781	8781	emma@tencent.com
    ring	张彦玲	8409	13928478661		80000768	8768	ring@tencent.com
    
    <class 'str'>
    ['13925288521', '25831029', '10054', '13823240555', '83850696', '10018', '28038', '13823202677', '82268556', '10040', '13501550210', '10037', '13828786611', '10158', '80000781', '13928478661', '80000768']
    
    
    vid	曹传宇	8276	13925288521	0755-25831029	10054	1054	david@tencent.com
    agong	贡海星	8267	13823240555	83850696	10018/28038	1018	agong@tencent.com
    hunter	刘化静	8277	13823202677	82268556	10040	1040	hunter@tencent.com
    norman	于　锐	8253	13501550210		10037	1037	yr@tencent.com
    king	王  星	8119	13828786611		10158	1158	king@tencent.com
    emma	刘旭民				80000781	8781	emma@tencent.com
    ring	张彦玲	8409	13928478661		80000768	8768	ring@tencent.com
    
    <class 'str'>
    ['13925288521', '25831029', '10054', '13823240555', '83850696', '10018', '28038', '13823202677', '82268556', '10040', '13501550210', '10037', '13828786611', '10158', '80000781', '13928478661', '80000768']
    

    Exception in Tkinter callback
    Traceback (most recent call last):
      File "C:\Users\money\Anaconda3\lib\tkinter\__init__.py", line 1702, in __call__
        return self.func(*args)
      File "<ipython-input-29-5aff54ee2484>", line 8, in go
        list.insert(tkinter.END,QQ)
    TypeError: descriptor 'insert' requires a 'list' object but received a 'str'
    Exception in Tkinter callback
    Traceback (most recent call last):
      File "C:\Users\money\Anaconda3\lib\tkinter\__init__.py", line 1702, in __call__
        return self.func(*args)
      File "<ipython-input-29-5aff54ee2484>", line 8, in go
        list.insert(tkinter.END,QQ)
    TypeError: descriptor 'insert' requires a 'list' object but received a 'str'
    Exception in Tkinter callback
    Traceback (most recent call last):
      File "C:\Users\money\Anaconda3\lib\tkinter\__init__.py", line 1702, in __call__
        return self.func(*args)
      File "<ipython-input-29-5aff54ee2484>", line 8, in go
        list.insert(tkinter.END,QQ)
    TypeError: descriptor 'insert' requires a 'list' object but received a 'str'
    

    
    
    vid	曹传宇	8276	13925288521	0755-25831029	10054	1054	david@tencent.com
    agong	贡海星	8267	13823240555	83850696	10018/28038	1018	agong@tencent.com
    hunter	刘化静	8277	13823202677	82268556	10040	1040	hunter@tencent.com
    norman	于　锐	8253	13501550210		10037	1037	yr@tencent.com
    king	王  星	8119	13828786611		10158	1158	king@tencent.com
    emma	刘旭民				80000781	8781	emma@tencent.com
    ring	张彦玲	8409	13928478661		80000768	8768	ring@tencent.com
    
    <class 'str'>
    ['13925288521', '25831029', '10054', '13823240555', '83850696', '10018', '28038', '13823202677', '82268556', '10040', '13501550210', '10037', '13828786611', '10158', '80000781', '13928478661', '80000768']
    
    
    vid	曹传宇	8276	13925288521	0755-25831029	10054	1054	david@tencent.com
    agong	贡海星	8267	13823240555	83850696	10018/28038	1018	agong@tencent.com
    hunter	刘化静	8277	13823202677	82268556	10040	1040	hunter@tencent.com
    norman	于　锐	8253	13501550210		10037	1037	yr@tencent.com
    king	王  星	8119	13828786611		10158	1158	king@tencent.com
    emma	刘旭民				80000781	8781	emma@tencent.com
    ring	张彦玲	8409	13928478661		80000768	8768	ring@tencent.com
    
    <class 'str'>
    ['13925288521', '25831029', '10054', '13823240555', '83850696', '10018', '28038', '13823202677', '82268556', '10040', '13501550210', '10037', '13828786611', '10158', '80000781', '13928478661', '80000768']
    

    Exception in Tkinter callback
    Traceback (most recent call last):
      File "C:\Users\money\Anaconda3\lib\tkinter\__init__.py", line 1702, in __call__
        return self.func(*args)
      File "<ipython-input-29-5aff54ee2484>", line 8, in go
        list.insert(tkinter.END,QQ)
    TypeError: descriptor 'insert' requires a 'list' object but received a 'str'
    

    
    
    vid	曹传宇	8276	13925288521	0755-25831029	10054	1054	david@tencent.com
    agong	贡海星	8267	13823240555	83850696	10018/28038	1018	agong@tencent.com
    hunter	刘化静	8277	13823202677	82268556	10040	1040	hunter@tencent.com
    norman	于　锐	8253	13501550210		10037	1037	yr@tencent.com
    king	王  星	8119	13828786611		10158	1158	king@tencent.com
    emma	刘旭民				80000781	8781	emma@tencent.com
    ring	张彦玲	8409	13928478661		80000768	8768	ring@tencent.com
    
    <class 'str'>
    ['13925288521', '25831029', '10054', '13823240555', '83850696', '10018', '28038', '13823202677', '82268556', '10040', '13501550210', '10037', '13828786611', '10158', '80000781', '13928478661', '80000768']
    

    Exception in Tkinter callback
    Traceback (most recent call last):
      File "C:\Users\money\Anaconda3\lib\tkinter\__init__.py", line 1702, in __call__
        return self.func(*args)
      File "<ipython-input-29-5aff54ee2484>", line 8, in go
        list.insert(tkinter.END,QQ)
    TypeError: descriptor 'insert' requires a 'list' object but received a 'str'
    


```python

```


```python

```
